<?xml version="1.0" ?>
<!-- =================================================================================== -->
<!-- |    This document was autogenerated by xacro from teo_humanoid_attach.urdf.xacro | -->
<!-- |    EDITING THIS FILE BY HAND IS NOT RECOMMENDED                                 | -->
<!-- =================================================================================== -->
<!--
  ROS urdf definition of TEO humanoid robot
  
  Author: Domingo Esteban, Raul Fernandez Fernandez
  RoboticsLab, Universidad Carlos III de Madrid
  
  This file loads TEO model with a basic visualization.
  If you want to convert this xacro file into an urdf file:
  $ rosrun xacro xacro.py teo_humanoid_simple_vis.urdf.xacro > teo_humanoid.urdf
	If you want to generate a SDF file from the generated URDF: (Requires gazebo)
	$ gzsdf print teo_humanoid.urdf > teo_humanoid.sdf
-->
<robot name="teo" xmlns:xacro="http://ros.org/wiki/xacro">
  <!-- TEO parameters -->
  <!-- TEO structure -->
  <!-- Include useful constants -->
  <!-- Include joint transmissions -->
  <!-- Use TEO platform -->
  <!-- **** Torso - base_link **** -->
  <!-- The robot is attached to the base link "world"-->
  

  <!--

  <link name="world"/>


  
  <joint name="base_waist" type="floating">
    <parent link="world"/>
    <child link="waist"/>
  </joint>
  
  -->

  <!-- Definitions of parts of the robot body -->
  <!-- *** TEO TORSO PARAMETERS -->
  <!-- Relation Kg - Volume Unit -->
  <!-- Link lengths -->
  <!--xacro:property name="waist_link2" value="0.287" /-->
  <!-- Minimum angles -->
  <!-- Maximum angles -->
  <!-- Effort limit of the angles -->
  <!-- Velocity limit of the angles-->
  <!-- Damping of the joints-->
  <!-- Friction of the joints-->
  <!-- IT'S NOT USED IN GAZEBO-->
  <!-- Joint reductions-->
  <!-- *** TORSO TREE -->
  <!-- Links -->
  <link name="waist">
    <inertial>
      <origin rpy="0 0 0" xyz="0.0 0.0 0.030531"/>
      <!-- <origin xyz="-0.011195 0.000002 0.030531" rpy="0 0 0"/> -->
      <mass value="1.0"/>
      <inertia ixx="1.672965e-2" ixy="-4.1e-7" ixz="-4.0359e-4" iyy="8.75441e-3" iyz="8.0e-8" izz="0.020584"/>
    </inertial>
    <!--     <inertial>
      <origin xyz="0.0 0.0 0.57136" rpy="0 0 0"/>
      <mass value="5.7044"/>
      <inertia
        ixx="0.019" ixy="0.000" ixz="0.000"
        iyy="0.018" iyz="0.000"
        izz="0.008" />
    </inertial> -->
    <!--     <inertial>
      <origin xyz="-0.011195 0.000002 0.030531" rpy="0 0 0"/>
      <mass value="1.0"/>
      <inertia
        ixx="1.672965e-5" ixy="-4.1e-10" ixz="-4.0359e-7"
        iyy="8.75441e-6" iyz="8.0e-11"
        izz="0.000020584" />
    </inertial> -->
    <visual>
      <origin rpy="0 0 0" xyz="0 0 0"/>
      <geometry>
        <mesh filename="package://teo_description/meshes/torso/waist-base.stl"/>
      </geometry>
      <material name="teoBlack"/>
    </visual>
    <collision>
      <origin rpy="0 0 0" xyz="0 0 0"/>
      <geometry>
        <mesh filename="package://teo_description/meshes/torso/waist-base.stl"/>
      </geometry>
    </collision>
    <visual>
      <origin rpy="0 0 0" xyz="0 0 0.07336"/>
      <geometry>
        <mesh filename="package://teo_description/meshes/torso/waist-link.stl"/>
      </geometry>
      <material name="teoGray"/>
    </visual>
    <collision>
      <origin rpy="0 0 0" xyz="0 0 0.07336"/>
      <geometry>
        <mesh filename="package://teo_description/meshes/torso/waist-link.stl"/>
      </geometry>
    </collision>
  </link>
  <link name="AxialTrunk">
    <inertial>
      <origin rpy="0 0 0" xyz="0.0 0.0 -0.024630"/>
      <!-- <origin xyz="-0.004091 -0.001037 -0.024630" rpy="0 0 0"/> -->
      <!-- <mass value="${prop_torso_kg_motor_vol_unit*0.000142}"/> -->
      <mass value="1.0"/>
      <!--     <inertia
			  ixx="0.66667" ixy="-0.25" ixz="-0.25"
				iyy="0.66667" iyz="-0.25"
				izz="0.66667" /> -->
      <!--       <inertia
        ixx="2.8026e-4" ixy="-2.9e-7" ixz="-4.22e-6"
        iyy="1.275e-4" iyz="4.4e-7"
        izz="2.0857e-4" /> -->
      <inertia ixx="0.028026e-2" ixy="-0.000029e-2" ixz="-0.000422e-2" iyy="0.012750e-2" iyz="0.000044e-2" izz="0.020857e-2"/>
    </inertial>
    <visual>
      <origin rpy="0 0 0" xyz="0 0 -0.001"/>
      <geometry>
        <mesh filename="package://teo_description/meshes/torso/waist-yaw.stl"/>
      </geometry>
      <material name="teoGray"/>
    </visual>
    <collision>
      <origin rpy="0 0 0" xyz="0 0 -0.001"/>
      <geometry>
        <mesh filename="package://teo_description/meshes/torso/waist-yaw.stl"/>
      </geometry>
    </collision>
  </link>
  <link name="FrontalTrunk">
    <inertial>
      <origin rpy="0 0 0" xyz="0.038788 -0.000008 0.221233"/>
      <!-- <origin xyz="0.0 -0.0 0.221233" rpy="0 0 0"/> -->
      <mass value="1.0"/>
      <!-- <inertia
        ixx="0.3563817" ixy="-5.5E-6" ixz="-0.014295"
        iyy="0.1422663" iyz="-2.205e-5" 
        izz="0.2704611" />
    </inertial> -->
      <inertia ixx="0.100973e-2" ixy="0.0" ixz="0.0" iyy="0.019175e-2" iyz="0.0" izz="0.100972e-2"/>
    </inertial>
    <visual>
      <origin rpy="0 0 0" xyz="0 0 0"/>
      <geometry>
        <mesh filename="package://teo_description/meshes/torso/waist-pitch.stl"/>
      </geometry>
      <material name="teoGray"/>
    </visual>
    <collision>
      <origin rpy="0 0 0" xyz="0 0 0"/>
      <geometry>
        <mesh filename="package://teo_description/meshes/torso/waist-pitch.stl"/>
      </geometry>
      <material name="teoGray"/>
    </collision>
    <visual>
      <origin rpy="0 0 0" xyz="0 0 0.06"/>
      <geometry>
        <mesh filename="package://teo_description/meshes/torso/torso.stl"/>
      </geometry>
      <material name="teoGray"/>
    </visual>
    <collision>
      <origin rpy="0 0 0" xyz="0 0 0.06"/>
      <geometry>
        <mesh filename="package://teo_description/meshes/torso/torso.stl"/>
      </geometry>
    </collision>
    <visual>
      <origin rpy="0 0 0" xyz="0 0.25486 0.305"/>
      <geometry>
        <mesh filename="package://teo_description/meshes/torso/L-torso-shoulder.stl"/>
      </geometry>
      <material name="teoGray"/>
    </visual>
    <collision>
      <origin rpy="0 0 0" xyz="0 0.25486 0.305"/>
      <geometry>
        <mesh filename="package://teo_description/meshes/torso/L-torso-shoulder.stl"/>
      </geometry>
    </collision>
    <visual>
      <origin rpy="0 0 0" xyz="0 -0.25486 0.305"/>
      <geometry>
        <mesh filename="package://teo_description/meshes/torso/R-torso-shoulder.stl"/>
      </geometry>
      <material name="LightGrey"/>
    </visual>
    <collision>
      <origin rpy="0 0 0" xyz="0 -0.25486 0.305"/>
      <geometry>
        <mesh filename="package://teo_description/meshes/torso/R-torso-shoulder.stl"/>
      </geometry>
    </collision>
  </link>
  <!-- Joints -->
  <joint name="AxialTrunk_joint" type="revolute">
    <parent link="waist"/>
    <child link="AxialTrunk"/>
    <origin rpy="0 0 0" xyz="0.0 0 0.1932"/>
    <axis xyz="0 0 1"/>
    <limit effort="30.0" lower="-1.0349802464" upper="0.8080874437" velocity="3.0"/>
  </joint>
  <joint name="FrontalTrunk_joint" type="revolute">
    <parent link="AxialTrunk"/>
    <child link="FrontalTrunk"/>
    <origin rpy="0 0 0" xyz="-0.0 0 0"/>
    <axis xyz="0 1 0"/>
    <limit effort="30.0" lower="-1.5777776438" upper="0.1762782545" velocity="3.0"/>
  </joint>
  <transmission name="waist_yaw_trans">
    <type>transmission_interface/SimpleTransmission</type>
    <joint name="AxialTrunk_joint">
      <hardwareInterface>PositionJointInterface</hardwareInterface>
    </joint>
    <actuator name="waist_yaw_motor">
      <mechanicalReduction>1.0</mechanicalReduction>
    </actuator>
  </transmission>
  <transmission name="waist_pitch_trans">
    <type>transmission_interface/SimpleTransmission</type>
    <joint name="FrontalTrunk_joint">
      <hardwareInterface>PositionJointInterface</hardwareInterface>
    </joint>
    <actuator name="waist_pitch_motor">
      <mechanicalReduction>1.0</mechanicalReduction>
    </actuator>
  </transmission>
  <!-- *** TEO HEAD PARAMETERS -->
  <!-- Relation Kg - Volume Unit -->
  <!-- Link lengths -->
  <!--xacro:property name="waist_link2" value="0.287" /-->
  <!-- head_link2 is an approximate value, right now this value is not relevant /-->
  <!-- Minimum angles -->
  <!-- Maximum angles -->
  <!-- Effort limit of the angles -->
  <!-- Velocity limit of the angles-->
  <!-- Damping of the joints-->
  <!-- Friction of the joints-->
  <!-- IT'S NOT USED IN GAZEBO-->
  <!-- Joint reductions-->
  <!-- *** HEAD TREE -->
  <!-- Links -->
  <link name="AxialNeck">
    <inertial>
      <origin rpy="0 0 0" xyz="0.0 0.0 -0.045"/>
      <mass value="1.0"/>
      <inertia ixx="0.028026e-2" ixy="-0.0" ixz="-0.0" iyy="0.028026e-2" iyz="0.0" izz="0.015756e-2"/>
    </inertial>
    <visual>
      <origin rpy="0 0 0" xyz="0 0 0.041"/>
      <geometry>
        <mesh filename="package://teo_description/meshes/head/neck.stl"/>
      </geometry>
      <material name="teoGray"/>
    </visual>
    <collision>
      <origin rpy="0 0 0" xyz="0 0 0.041"/>
      <geometry>
        <mesh filename="package://teo_description/meshes/head/neck.stl"/>
      </geometry>
    </collision>
  </link>
  <link name="FrontalNeck">
    <inertial>
      <origin rpy="0 0 0" xyz="-0.004280 0.0 0.105394"/>
      <mass value="1.0"/>
      <inertia ixx="1.469540" ixy="-0.000003" ixz="-0.012716" iyy="1.610027" iyz="0.000005" izz="2.205351"/>
    </inertial>
    <visual>
      <origin rpy="0 0 0" xyz="0 0 0"/>
      <geometry>
        <mesh filename="package://teo_description/meshes/head/head.stl"/>
      </geometry>
      <material name="teoGray"/>
    </visual>
    <collision>
      <origin rpy="0 0 0" xyz="0 0 0"/>
      <geometry>
        <mesh filename="package://teo_description/meshes/head/head.stl"/>
      </geometry>
    </collision>
  </link>
  <!-- Joints -->
  <joint name="AxialNeck_joint" type="revolute">
    <parent link="FrontalTrunk"/>
    <child link="AxialNeck"/>
    <origin rpy="0 0 0" xyz="0 0 0.305"/>
    <axis xyz="0 0 1"/>
    <limit effort="30.0" lower="-0.506145483078" upper="0.146607657168" velocity="3.0"/>
  </joint>
  <joint name="FrontalNeck_joint" type="revolute">
    <parent link="AxialNeck"/>
    <child link="FrontalNeck"/>
    <origin rpy="0 0 0" xyz="0 0 0.13"/>
    <axis xyz="0 1 0"/>
    <limit effort="30.0" lower="-1.27409035396" upper="1.27409035396" velocity="3.0"/>
  </joint>
  <transmission name="waist_yaw_trans">
    <type>transmission_interface/SimpleTransmission</type>
    <joint name="AxialTrunk_joint">
      <hardwareInterface>PositionJointInterface</hardwareInterface>
    </joint>
    <actuator name="waist_yaw_motor">
      <mechanicalReduction>1.0</mechanicalReduction>
    </actuator>
  </transmission>
  <transmission name="waist_pitch_trans">
    <type>transmission_interface/SimpleTransmission</type>
    <joint name="FrontalTrunk_joint">
      <hardwareInterface>PositionJointInterface</hardwareInterface>
    </joint>
    <actuator name="waist_pitch_motor">
      <mechanicalReduction>1.0</mechanicalReduction>
    </actuator>
  </transmission>
  <!-- *** TEO LEG PARAMETERS -->
  <!-- Relation Kg - Volume Unit -->
  <!-- Relation Kg - Volume Unit -->
  <!-- Relation Kg - Volume Unit -->
  <!-- Link lengths -->
  <!-- Hip -->
  <!-- Hip -->
  <!-- Femur -->
  <!-- Tibia -->
  <!-- Patella -->
  <!-- Astragalus -->
  <!-- Minimum angles right leg -->
  <!-- Maximum angles right leg -->
  <!-- Effort limit of the angles -->
  <!-- Velocity limit of the angles-->
  <!-- Damping of the joints-->
  <!-- Friction of the joints-->
  <!-- IT'S NOT USED IN GAZEBO-->
  <!-- Joint reductions-->
  <!-- *** TEO LEG MACROS -->
  <!-- Links -->
  <!-- Joints -->
  <link name="AxialLeftHip">
    <inertial>
      <origin rpy="0 0 0" xyz="0.0 -0.0 0.0"/>
      <mass value="1.0"/>
      <inertia ixx="3.4076E-4" ixy="-0.0" ixz="5.4E-7" iyy="5.7638E-4" iyz="-0.0" izz="0.037186e-2"/>
    </inertial>
    <visual>
      <origin rpy="0 0 0" xyz="0 0 0"/>
      <geometry>
        <mesh filename="package://teo_description/meshes/legs/l_hip_yaw.stl"/>
      </geometry>
      <material name="teoGray"/>
    </visual>
    <collision>
      <origin rpy="0 0 0" xyz="0 0 0"/>
      <geometry>
        <mesh filename="package://teo_description/meshes/legs/l_hip_yaw.stl"/>
      </geometry>
    </collision>
  </link>
  <link name="SagittalLeftHip">
    <inertial>
      <origin rpy="0 0 0" xyz="0.0 -0.0 -0.017753"/>
      <mass value="1.0"/>
      <inertia ixx="3.6847E-4" ixy="-4.34e-06" ixz="1.0E-8" iyy="1.9052E-4" iyz="-0.0" izz="4.5536E-4"/>
    </inertial>
    <visual>
      <origin rpy="0 0 0" xyz="0 0 0"/>
      <geometry>
        <mesh filename="package://teo_description/meshes/legs/l_hip_pitch.stl"/>
      </geometry>
      <material name="teoGray"/>
    </visual>
    <collision>
      <origin rpy="0 0 0" xyz="0 0 0"/>
      <geometry>
        <mesh filename="package://teo_description/meshes/legs/l_hip_pitch.stl"/>
      </geometry>
    </collision>
  </link>
  <link name="FrontalLeftHip">
    <inertial>
      <origin rpy="0 0 0" xyz="0.0 -0.0 -0.17257"/>
      <mass value="1.0"/>
      <inertia ixx="4.453648E-2" ixy="1e-08" ixz="0.00130498" iyy="4.46349E-2" iyz="-4e-08" izz="2.207083E-2"/>
    </inertial>
    <visual>
      <origin rpy="0 0 0" xyz="0 0 0"/>
      <geometry>
        <mesh filename="package://teo_description/meshes/legs/l_femur.stl"/>
      </geometry>
      <material name="teoGray"/>
    </visual>
    <collision>
      <origin rpy="0 0 0" xyz="0 0 0"/>
      <geometry>
        <mesh filename="package://teo_description/meshes/legs/l_femur.stl"/>
      </geometry>
    </collision>
  </link>
  <link name="FrontalLeftKnee">
    <inertial>
      <origin rpy="0 0 0" xyz="0.0 -0.0 -0.142721"/>
      <mass value="1.0"/>
      <inertia ixx="4.644211E-2" ixy="-0.0" ixz="-7.32E-6" iyy="4.548272E-2" iyz="1e-08" izz="8.16616E-3"/>
    </inertial>
    <visual>
      <origin rpy="0 0 0" xyz="0.0 0.0 0.0"/>
      <geometry>
        <mesh filename="package://teo_description/meshes/legs/l_tibia.stl"/>
      </geometry>
      <material name="teoGray"/>
    </visual>
    <collision>
      <origin rpy="0 0 0" xyz="0.0 0.0 0.0"/>
      <geometry>
        <mesh filename="package://teo_description/meshes/legs/l_tibia.stl"/>
      </geometry>
    </collision>
  </link>
  <link name="FrontalLeftAnkle">
    <inertial>
      <origin rpy="0 0 0" xyz="0.0 -0.0 0.028198"/>
      <mass value="1.0"/>
      <inertia ixx="0.010237e-2" ixy="-1.4e-05" ixz="0.0" iyy="0.035107e-2" iyz="0.0" izz="0.035006e-2"/>
    </inertial>
    <visual>
      <origin rpy="0 0 0" xyz="0 0 0"/>
      <geometry>
        <mesh filename="package://teo_description/meshes/legs/l_ankle_pitch.stl"/>
      </geometry>
      <material name="teoGray"/>
    </visual>
    <collision>
      <origin rpy="0 0 0" xyz="0 0 0"/>
      <geometry>
        <mesh filename="package://teo_description/meshes/legs/l_ankle_pitch.stl"/>
      </geometry>
    </collision>
  </link>
  <link name="SagittalLeftAnkle">
    <inertial>
      <origin rpy="0 0 0" xyz="0.0 -0.0 -0.042127"/>
      <mass value="1.0"/>
      <inertia ixx="2.6324E-4" ixy="-0.0" ixz="7.4E-6" iyy="0.000571" iyz="-0.0" izz="4.633E-4"/>
    </inertial>
    <visual>
      <origin rpy="0 0 0" xyz="0 0 0"/>
      <geometry>
        <mesh filename="package://teo_description/meshes/legs/l_ankle_roll.stl"/>
      </geometry>
      <material name="teoGray"/>
    </visual>
    <collision>
      <origin rpy="0 0 0" xyz="0 0 0"/>
      <geometry>
        <mesh filename="package://teo_description/meshes/legs/l_ankle_roll.stl"/>
      </geometry>
    </collision>
    <visual>
      <origin rpy="0 0 0" xyz="0 0 -0.073"/>
      <geometry>
        <mesh filename="package://teo_description/meshes/legs/l_ankle_sensorFT.stl"/>
      </geometry>
    </visual>
    <collision>
      <origin rpy="0 0 0" xyz="0 0 -0.073"/>
      <geometry>
        <mesh filename="package://teo_description/meshes/legs/l_ankle_sensorFT.stl"/>
      </geometry>
    </collision>
  </link>
  <link name="LeftFoot">
    <inertial>
      <origin rpy="0 0 0" xyz="0.022629 -0.002448 0.011325"/>
      <mass value="1.0"/>
      <inertia ixx="0.065992e-2" ixy="-0.00010716" ixz="0.008960e-2" iyy="0.167825e-2" iyz="8.47e-06" izz="0.225319e-2"/>
    </inertial>
    <visual>
      <origin rpy="0 0 0" xyz="0 0 0"/>
      <geometry>
        <mesh filename="package://teo_description/meshes/legs/l_foot.stl"/>
      </geometry>
      <material name="teoGray"/>
    </visual>
    <collision>
      <origin rpy="0 0 0" xyz="0 0 0"/>
      <geometry>
        <mesh filename="package://teo_description/meshes/legs/l_foot.stl"/>
      </geometry>
    </collision>
    <visual>
      <origin rpy="0 0 0" xyz="0 0 0"/>
      <geometry>
        <mesh filename="package://teo_description/meshes/legs/l_union_sensorFT_foot.stl"/>
      </geometry>
      <material name="teoBlue"/>
    </visual>
    <collision>
      <origin rpy="0 0 0" xyz="0 0 0"/>
      <geometry>
        <mesh filename="package://teo_description/meshes/legs/l_union_sensorFT_foot.stl"/>
      </geometry>
    </collision>
  </link>
  <link name="AxialRightHip">
    <inertial>
      <origin rpy="0 0 0" xyz="0.0 0.0 0.0"/>
      <mass value="1.0"/>
      <inertia ixx="3.4076E-4" ixy="0.0" ixz="5.4E-7" iyy="5.7638E-4" iyz="0.0" izz="0.037186e-2"/>
    </inertial>
    <visual>
      <origin rpy="0 0 0" xyz="0 0 0"/>
      <geometry>
        <mesh filename="package://teo_description/meshes/legs/r_hip_yaw.stl"/>
      </geometry>
      <material name="teoGray"/>
    </visual>
    <collision>
      <origin rpy="0 0 0" xyz="0 0 0"/>
      <geometry>
        <mesh filename="package://teo_description/meshes/legs/r_hip_yaw.stl"/>
      </geometry>
    </collision>
  </link>
  <link name="SagittalRightHip">
    <inertial>
      <origin rpy="0 0 0" xyz="0.0 0.0 -0.017753"/>
      <mass value="1.0"/>
      <inertia ixx="3.6847E-4" ixy="4.34e-06" ixz="1.0E-8" iyy="1.9052E-4" iyz="0.0" izz="4.5536E-4"/>
    </inertial>
    <visual>
      <origin rpy="0 0 0" xyz="0 0 0"/>
      <geometry>
        <mesh filename="package://teo_description/meshes/legs/r_hip_pitch.stl"/>
      </geometry>
      <material name="teoGray"/>
    </visual>
    <collision>
      <origin rpy="0 0 0" xyz="0 0 0"/>
      <geometry>
        <mesh filename="package://teo_description/meshes/legs/r_hip_pitch.stl"/>
      </geometry>
    </collision>
  </link>
  <link name="FrontalRightHip">
    <inertial>
      <origin rpy="0 0 0" xyz="0.0 0.0 -0.17257"/>
      <mass value="1.0"/>
      <inertia ixx="4.453648E-2" ixy="-1e-08" ixz="0.00130498" iyy="4.46349E-2" iyz="4e-08" izz="2.207083E-2"/>
    </inertial>
    <visual>
      <origin rpy="0 0 0" xyz="0 0 0"/>
      <geometry>
        <mesh filename="package://teo_description/meshes/legs/r_femur.stl"/>
      </geometry>
      <material name="teoGray"/>
    </visual>
    <collision>
      <origin rpy="0 0 0" xyz="0 0 0"/>
      <geometry>
        <mesh filename="package://teo_description/meshes/legs/r_femur.stl"/>
      </geometry>
    </collision>
  </link>
  <link name="FrontalRightKnee">
    <inertial>
      <origin rpy="0 0 0" xyz="0.0 0.0 -0.142721"/>
      <mass value="1.0"/>
      <inertia ixx="4.644211E-2" ixy="0.0" ixz="-7.32E-6" iyy="4.548272E-2" iyz="-1e-08" izz="8.16616E-3"/>
    </inertial>
    <visual>
      <origin rpy="0 0 0" xyz="0.0 0.0 0.0"/>
      <geometry>
        <mesh filename="package://teo_description/meshes/legs/r_tibia.stl"/>
      </geometry>
      <material name="teoGray"/>
    </visual>
    <collision>
      <origin rpy="0 0 0" xyz="0.0 0.0 0.0"/>
      <geometry>
        <mesh filename="package://teo_description/meshes/legs/r_tibia.stl"/>
      </geometry>
    </collision>
  </link>
  <link name="FrontalRightAnkle">
    <inertial>
      <origin rpy="0 0 0" xyz="0.0 0.0 0.028198"/>
      <mass value="1.0"/>
      <inertia ixx="0.010237e-2" ixy="1.4e-05" ixz="0.0" iyy="0.035107e-2" iyz="-0.0" izz="0.035006e-2"/>
    </inertial>
    <visual>
      <origin rpy="0 0 0" xyz="0 0 0"/>
      <geometry>
        <mesh filename="package://teo_description/meshes/legs/r_ankle_pitch.stl"/>
      </geometry>
      <material name="teoGray"/>
    </visual>
    <collision>
      <origin rpy="0 0 0" xyz="0 0 0"/>
      <geometry>
        <mesh filename="package://teo_description/meshes/legs/r_ankle_pitch.stl"/>
      </geometry>
    </collision>
  </link>
  <link name="SagittalRightAnkle">
    <inertial>
      <origin rpy="0 0 0" xyz="0.0 0.0 -0.042127"/>
      <mass value="1.0"/>
      <inertia ixx="2.6324E-4" ixy="0.0" ixz="7.4E-6" iyy="0.000571" iyz="0.0" izz="4.633E-4"/>
    </inertial>
    <visual>
      <origin rpy="0 0 0" xyz="0 0 0"/>
      <geometry>
        <mesh filename="package://teo_description/meshes/legs/r_ankle_roll.stl"/>
      </geometry>
      <material name="teoGray"/>
    </visual>
    <collision>
      <origin rpy="0 0 0" xyz="0 0 0"/>
      <geometry>
        <mesh filename="package://teo_description/meshes/legs/r_ankle_roll.stl"/>
      </geometry>
    </collision>
    <visual>
      <origin rpy="0 0 0" xyz="0 0 -0.073"/>
      <geometry>
        <mesh filename="package://teo_description/meshes/legs/r_ankle_sensorFT.stl"/>
      </geometry>
    </visual>
    <collision>
      <origin rpy="0 0 0" xyz="0 0 -0.073"/>
      <geometry>
        <mesh filename="package://teo_description/meshes/legs/r_ankle_sensorFT.stl"/>
      </geometry>
    </collision>
  </link>
  <link name="RightFoot">
    <inertial>
      <origin rpy="0 0 0" xyz="0.022629 0.002448 0.011325"/>
      <mass value="1.0"/>
      <inertia ixx="0.065992e-2" ixy="0.00010716" ixz="0.008960e-2" iyy="0.167825e-2" iyz="-8.47e-06" izz="0.225319e-2"/>
    </inertial>
    <visual>
      <origin rpy="0 0 0" xyz="0 0 0"/>
      <geometry>
        <mesh filename="package://teo_description/meshes/legs/r_foot.stl"/>
      </geometry>
      <material name="teoGray"/>
    </visual>
    <collision>
      <origin rpy="0 0 0" xyz="0 0 0"/>
      <geometry>
        <mesh filename="package://teo_description/meshes/legs/r_foot.stl"/>
      </geometry>
    </collision>
    <visual>
      <origin rpy="0 0 0" xyz="0 0 0"/>
      <geometry>
        <mesh filename="package://teo_description/meshes/legs/r_union_sensorFT_foot.stl"/>
      </geometry>
      <material name="teoBlue"/>
    </visual>
    <collision>
      <origin rpy="0 0 0" xyz="0 0 0"/>
      <geometry>
        <mesh filename="package://teo_description/meshes/legs/r_union_sensorFT_foot.stl"/>
      </geometry>
    </collision>
  </link>
  <joint name="AxialLeftHip_joint" type="revolute">
    <parent link="waist"/>
    <child link="AxialLeftHip"/>
    <origin rpy="0 0 0" xyz="0 0.146 -0.092"/>
    <axis xyz="0 0 1"/>
    <limit effort="45.0" lower="-0.4869468613" upper="0.5724679947" velocity="4.0"/>
    <dynamics damping="1.0" friction="1.0"/>
  </joint>
  <joint name="SagittalLeftHip_joint" type="revolute">
    <parent link="AxialLeftHip"/>
    <child link="SagittalLeftHip"/>
    <origin rpy="0 0 0" xyz="0 0 0"/>
    <axis xyz="1 0 0"/>
    <limit effort="65.0" lower="-0.2181661565" upper="0.2478367538" velocity="4.0"/>
    <dynamics damping="1.0" friction="1.0"/>
  </joint>
  <joint name="FrontalLeftHip_joint" type="revolute">
    <parent link="SagittalLeftHip"/>
    <child link="FrontalLeftHip"/>
    <origin rpy="0 0 0" xyz="0 0 0"/>
    <axis xyz="0 1 0"/>
    <limit effort="60.0" lower="-0.5515240436" upper="0.7382742736" velocity="4.0"/>
    <dynamics damping="1.0" friction="1.0"/>
  </joint>
  <joint name="FrontalLeftKnee_joint" type="revolute">
    <parent link="FrontalLeftHip"/>
    <child link="FrontalLeftKnee"/>
    <origin rpy="0 0 0" xyz="0 0 -0.33"/>
    <axis xyz="0 1 0"/>
    <limit effort="140.0" lower="-1.0698868315" upper="1.4381513036" velocity="4.0"/>
    <dynamics damping="1.0" friction="1.0"/>
  </joint>
  <joint name="FrontalLeftAnkle_joint" type="revolute">
    <parent link="FrontalLeftKnee"/>
    <child link="FrontalLeftAnkle"/>
    <origin rpy="0 0 0" xyz="0 -0.0175 -0.3"/>
    <axis xyz="0 1 0"/>
    <limit effort="85.0" lower="-0.4031710572" upper="0.44331363" velocity="4.0"/>
    <dynamics damping="1.0" friction="1.0"/>
  </joint>
  <joint name="SagittalLeftAnkle_joint" type="revolute">
    <parent link="FrontalLeftAnkle"/>
    <child link="SagittalLeftAnkle"/>
    <origin rpy="0 0 0" xyz="0 0 0"/>
    <axis xyz="1 0 0"/>
    <limit effort="65.0" lower="-0.7417649321" upper="0.3473205211" velocity="4.0"/>
    <dynamics damping="1.0" friction="1.0"/>
  </joint>
  <joint name="LeftFoot_joint" type="fixed">
    <parent link="SagittalLeftAnkle"/>
    <child link="LeftFoot"/>
    <origin rpy="0 0 0" xyz="0 0 -0.123005"/>
  </joint>
  <!-- <joint name="${side}_sole_fixed" type="fixed">	    
      <parent link="world"/>    
      <child link="${side}_sole"/>
    </joint> -->
  <!--TODO: Delete the fixed joints using a /map->/base_link publisher for the control-->
  <transmission name="l_hip_yaw_trans">
    <type>transmission_interface/SimpleTransmission</type>
    <joint name="AxialLeftHip_joint">
      <hardwareInterface>PositionJointInterface</hardwareInterface>
    </joint>
    <actuator name="l_hip_yaw_motor">
      <hardwareInterface>PositionJointInterface</hardwareInterface>
      <mechanicalReduction>1.0</mechanicalReduction>
    </actuator>
  </transmission>
  <transmission name="l_hip_roll_trans">
    <type>transmission_interface/SimpleTransmission</type>
    <joint name="SagittalLeftHip_joint">
      <hardwareInterface>PositionJointInterface</hardwareInterface>
    </joint>
    <actuator name="l_hip_roll_motor">
      <hardwareInterface>PositionJointInterface</hardwareInterface>
      <mechanicalReduction>1.0</mechanicalReduction>
    </actuator>
  </transmission>
  <transmission name="l_hip_pitch_trans">
    <type>transmission_interface/SimpleTransmission</type>
    <joint name="FrontalLeftHip_joint">
      <hardwareInterface>PositionJointInterface</hardwareInterface>
    </joint>
    <actuator name="l_hip_pitch_motor">
      <hardwareInterface>PositionJointInterface</hardwareInterface>
      <mechanicalReduction>1.0</mechanicalReduction>
    </actuator>
  </transmission>
  <transmission name="l_knee_pitch_trans">
    <type>transmission_interface/SimpleTransmission</type>
    <joint name="FrontalLeftKnee_joint">
      <hardwareInterface>PositionJointInterface</hardwareInterface>
    </joint>
    <actuator name="l_knee_pitch_motor">
      <hardwareInterface>PositionJointInterface</hardwareInterface>
      <mechanicalReduction>1.0</mechanicalReduction>
    </actuator>
  </transmission>
  <transmission name="l_ankle_pitch_trans">
    <type>transmission_interface/SimpleTransmission</type>
    <joint name="FrontalLeftAnkle_joint">
      <hardwareInterface>PositionJointInterface</hardwareInterface>
    </joint>
    <actuator name="l_ankle_pitch_motor">
      <hardwareInterface>PositionJointInterface</hardwareInterface>
      <mechanicalReduction>1.0</mechanicalReduction>
    </actuator>
  </transmission>
  <transmission name="l_ankle_roll_trans">
    <type>transmission_interface/SimpleTransmission</type>
    <joint name="SagittalLeftAnkle_joint">
      <hardwareInterface>PositionJointInterface</hardwareInterface>
    </joint>
    <actuator name="l_ankle_roll_motor">
      <hardwareInterface>PositionJointInterface</hardwareInterface>
      <mechanicalReduction>1.0</mechanicalReduction>
    </actuator>
  </transmission>
  <joint name="AxialRightHip_joint" type="revolute">
    <parent link="waist"/>
    <child link="AxialRightHip"/>
    <origin rpy="0 0 0" xyz="0 -0.146 -0.092"/>
    <axis xyz="0 0 1"/>
    <limit effort="45.0" lower="-0.5724679947" upper="0.4869468613" velocity="4.0"/>
    <dynamics damping="1.0" friction="1.0"/>
  </joint>
  <joint name="SagittalRightHip_joint" type="revolute">
    <parent link="AxialRightHip"/>
    <child link="SagittalRightHip"/>
    <origin rpy="0 0 0" xyz="0 0 0"/>
    <axis xyz="1 0 0"/>
    <limit effort="65.0" lower="-0.2478367538" upper="0.2181661565" velocity="4.0"/>
    <dynamics damping="1.0" friction="1.0"/>
  </joint>
  <joint name="FrontalRightHip_joint" type="revolute">
    <parent link="SagittalRightHip"/>
    <child link="FrontalRightHip"/>
    <origin rpy="0 0 0" xyz="0 0 0"/>
    <axis xyz="0 1 0"/>
    <limit effort="60.0" lower="-0.5515240436" upper="0.7382742736" velocity="4.0"/>
    <dynamics damping="1.0" friction="1.0"/>
  </joint>
  <joint name="FrontalRightKnee_joint" type="revolute">
    <parent link="FrontalRightHip"/>
    <child link="FrontalRightKnee"/>
    <origin rpy="0 0 0" xyz="0 0 -0.33"/>
    <axis xyz="0 1 0"/>
    <limit effort="140.0" lower="-1.0698868315" upper="1.4381513036" velocity="4.0"/>
    <dynamics damping="1.0" friction="1.0"/>
  </joint>
  <joint name="FrontalRightAnkle_joint" type="revolute">
    <parent link="FrontalRightKnee"/>
    <child link="FrontalRightAnkle"/>
    <origin rpy="0 0 0" xyz="0 0.0175 -0.3"/>
    <axis xyz="0 1 0"/>
    <limit effort="85.0" lower="-0.4031710572" upper="0.44331363" velocity="4.0"/>
    <dynamics damping="1.0" friction="1.0"/>
  </joint>
  <joint name="SagittalRightAnkle_joint" type="revolute">
    <parent link="FrontalRightAnkle"/>
    <child link="SagittalRightAnkle"/>
    <origin rpy="0 0 0" xyz="0 0 0"/>
    <axis xyz="1 0 0"/>
    <limit effort="65.0" lower="-0.3473205211" upper="0.7417649321" velocity="4.0"/>
    <dynamics damping="1.0" friction="1.0"/>
  </joint>
  <joint name="RightFoot_joint" type="fixed">
    <parent link="SagittalRightAnkle"/>
    <child link="RightFoot"/>
    <origin rpy="0 0 0" xyz="0 0 -0.123005"/>
  </joint>
  <!-- <joint name="${side}_sole_fixed" type="fixed">	    
      <parent link="world"/>    
      <child link="${side}_sole"/>
    </joint> -->
  <!--TODO: Delete the fixed joints using a /map->/base_link publisher for the control-->
  <transmission name="r_hip_yaw_trans">
    <type>transmission_interface/SimpleTransmission</type>
    <joint name="AxialRightHip_joint">
      <hardwareInterface>PositionJointInterface</hardwareInterface>
    </joint>
    <actuator name="r_hip_yaw_motor">
      <hardwareInterface>PositionJointInterface</hardwareInterface>
      <mechanicalReduction>1.0</mechanicalReduction>
    </actuator>
  </transmission>
  <transmission name="r_hip_roll_trans">
    <type>transmission_interface/SimpleTransmission</type>
    <joint name="SagittalRightHip_joint">
      <hardwareInterface>PositionJointInterface</hardwareInterface>
    </joint>
    <actuator name="r_hip_roll_motor">
      <hardwareInterface>PositionJointInterface</hardwareInterface>
      <mechanicalReduction>1.0</mechanicalReduction>
    </actuator>
  </transmission>
  <transmission name="r_hip_pitch_trans">
    <type>transmission_interface/SimpleTransmission</type>
    <joint name="FrontalRightHip_joint">
      <hardwareInterface>PositionJointInterface</hardwareInterface>
    </joint>
    <actuator name="r_hip_pitch_motor">
      <hardwareInterface>PositionJointInterface</hardwareInterface>
      <mechanicalReduction>1.0</mechanicalReduction>
    </actuator>
  </transmission>
  <transmission name="r_knee_pitch_trans">
    <type>transmission_interface/SimpleTransmission</type>
    <joint name="FrontalRightKnee_joint">
      <hardwareInterface>PositionJointInterface</hardwareInterface>
    </joint>
    <actuator name="r_knee_pitch_motor">
      <hardwareInterface>PositionJointInterface</hardwareInterface>
      <mechanicalReduction>1.0</mechanicalReduction>
    </actuator>
  </transmission>
  <transmission name="r_ankle_pitch_trans">
    <type>transmission_interface/SimpleTransmission</type>
    <joint name="FrontalRightAnkle_joint">
      <hardwareInterface>PositionJointInterface</hardwareInterface>
    </joint>
    <actuator name="r_ankle_pitch_motor">
      <hardwareInterface>PositionJointInterface</hardwareInterface>
      <mechanicalReduction>1.0</mechanicalReduction>
    </actuator>
  </transmission>
  <transmission name="r_ankle_roll_trans">
    <type>transmission_interface/SimpleTransmission</type>
    <joint name="SagittalRightAnkle_joint">
      <hardwareInterface>PositionJointInterface</hardwareInterface>
    </joint>
    <actuator name="r_ankle_roll_motor">
      <hardwareInterface>PositionJointInterface</hardwareInterface>
      <mechanicalReduction>1.0</mechanicalReduction>
    </actuator>
  </transmission>
  <!-- *** TEO ARM PARAMETERS -->
  <!-- Link lengths (meters)-->
  <!-- Clavicle -->
  <!-- Humerus -->
  <!-- Ulna -->
  <!-- Minimum angles right arm  (degrees) -->
  <!-- Maximum angles right arm (degrees) -->
  <!-- Effort limit of the angles -->
  <!-- Velocity limit of the angles-->
  <!-- Damping of the joints-->
  <!-- Friction of the joints-->
  <!-- IT'S NOT USED IN GAZEBO-->
  <!-- Joint reductions-->
  <!-- *** TEO ARM MACROS -->
  <!-- Links -->
  <!-- Joints -->
  <link name="FrontalLeftShoulder">
    <inertial>
      <origin rpy="0 0 0" xyz="0.0 0.0 0.0"/>
      <mass value="0.005"/>
      <inertia ixx="0.059121e-2" ixy="0.000603e-2" ixz="0.000103e-2" iyy="0.024956e-2" iyz="0.005131e-2" izz="0.050653e-2"/>
    </inertial>
    <visual>
      <origin rpy="0 0 0" xyz="0 0 0"/>
      <geometry>
        <mesh filename="package://teo_description/meshes/arms/l_shoulder_pitch.stl"/>
      </geometry>
      <material name="teoGray"/>
    </visual>
    <collision>
      <origin rpy="0 0 0" xyz="0 0 0"/>
      <geometry>
        <mesh filename="package://teo_description/meshes/arms/l_shoulder_pitch.stl"/>
      </geometry>
    </collision>
  </link>
  <link name="SagittalLeftShoulder">
    <inertial>
      <origin rpy="0 0 0" xyz="0.0 0.0 0.0"/>
      <mass value="0.005"/>
      <inertia ixx="0.018036e-2" ixy="-0.000773e-2" ixz="0.002406e-2" iyy="0.024499e-2" iyz="0.001826e-2" izz="0.013143e-2"/>
    </inertial>
    <visual>
      <origin rpy="0 0 0" xyz="0 0 0"/>
      <geometry>
        <mesh filename="package://teo_description/meshes/arms/l_shoulder_roll.stl"/>
      </geometry>
      <material name="teoGray"/>
    </visual>
    <collision>
      <origin rpy="0 0 0" xyz="0 0 0"/>
      <geometry>
        <mesh filename="package://teo_description/meshes/arms/l_shoulder_roll.stl"/>
      </geometry>
    </collision>
  </link>
  <link name="AxialLeftShoulder">
    <inertial>
      <origin rpy="0 0 0" xyz="0.0 0.0 0.0"/>
      <mass value="1.750625"/>
      <inertia ixx="0.227681e-2" ixy="0.0" ixz="0.0" iyy="0.224821e-2" iyz="-0.000684e-2" izz="0.032283e-2"/>
    </inertial>
    <visual>
      <origin rpy="0 0 0" xyz="0 0 -0.12126"/>
      <geometry>
        <mesh filename="package://teo_description/meshes/arms/l_shoulder_yaw.stl"/>
      </geometry>
      <material name="teoGray"/>
    </visual>
    <collision>
      <origin rpy="0 0 0" xyz="0 0 -0.12126"/>
      <geometry>
        <mesh filename="package://teo_description/meshes/arms/l_shoulder_yaw.stl"/>
      </geometry>
    </collision>
    <visual>
      <origin rpy="0 0 0" xyz="0 0 -0.27651"/>
      <geometry>
        <mesh filename="package://teo_description/meshes/arms/l_humerus.stl"/>
      </geometry>
      <material name="teoGray"/>
    </visual>
    <collision>
      <origin rpy="0 0 0" xyz="0 0 -0.27651"/>
      <geometry>
        <mesh filename="package://teo_description/meshes/arms/l_humerus.stl"/>
      </geometry>
    </collision>
    <visual>
      <origin rpy="0 0 0" xyz="0 0 -0.28351"/>
      <geometry>
        <mesh filename="package://teo_description/meshes/arms/l_union_humerus_elbow.stl"/>
      </geometry>
      <material name="teoGray"/>
    </visual>
    <collision>
      <origin rpy="0 0 0" xyz="0 0 -0.28351"/>
      <geometry>
        <mesh filename="package://teo_description/meshes/arms/l_union_humerus_elbow.stl"/>
      </geometry>
    </collision>
  </link>
  <link name="FrontalLeftElbow">
    <inertial>
      <origin rpy="0 0 0" xyz="0.0 0.001 -0.000588"/>
      <mass value="2.396"/>
      <inertia ixx="0.059390e-2" ixy="0.0" ixz="0.0" iyy="0.060871e-2" iyz="-0.0" izz="0.023257e-2"/>
       --&gt;
      
    </inertial>
    <visual>
      <origin rpy="0 0 0" xyz="0 0 0"/>
      <geometry>
        <mesh filename="package://teo_description/meshes/arms/l_elbow_pitch.stl"/>
      </geometry>
      <material name="teoGray"/>
    </visual>
    <collision>
      <origin rpy="0 0 0" xyz="0 0 0"/>
      <geometry>
        <mesh filename="package://teo_description/meshes/arms/l_elbow_pitch.stl"/>
      </geometry>
    </collision>
    <visual>
      <origin rpy="0 0 0" xyz="0 0 -0.11324"/>
      <geometry>
        <mesh filename="package://teo_description/meshes/arms/l_elbow_link.stl"/>
      </geometry>
      <material name="teoGray"/>
    </visual>
    <collision>
      <origin rpy="0 0 0" xyz="0 0 -0.11324"/>
      <geometry>
        <mesh filename="package://teo_description/meshes/arms/l_elbow_link.stl"/>
      </geometry>
    </collision>
    <visual>
      <origin rpy="0 0 0" xyz="0 0 -0.11324"/>
      <geometry>
        <mesh filename="package://teo_description/meshes/arms/l_union_elbow_wrist.stl"/>
      </geometry>
      <material name="teoGray"/>
    </visual>
    <collision>
      <origin rpy="0 0 0" xyz="0 0 -0.11324"/>
      <geometry>
        <mesh filename="package://teo_description/meshes/arms/l_union_elbow_wrist.stl"/>
      </geometry>
    </collision>
  </link>
  <link name="AxialLeftWrist">
    <inertial>
      <origin rpy="0 0 0" xyz="-0.004657 -0.001356 0.035884"/>
      <mass value="0.005"/>
      <inertia ixx="0.004543e-2" ixy="0.000068e-2" ixz="0.000070e-2" iyy="0.003969e-2" iyz="-0.000074e-2" izz="0.002118e-2"/>
    </inertial>
    <visual>
      <origin rpy="0 0 0" xyz="0 0 0"/>
      <geometry>
        <mesh filename="package://teo_description/meshes/arms/l_wrist_yaw.stl"/>
      </geometry>
      <material name="teoGray"/>
    </visual>
    <collision>
      <origin rpy="0 0 0" xyz="0 0 0"/>
      <geometry>
        <mesh filename="package://teo_description/meshes/arms/l_wrist_yaw.stl"/>
      </geometry>
    </collision>
  </link>
  <link name="FrontalLeftWrist">
    <inertial>
      <origin rpy="0 0 0" xyz="-0.002438 0.004651 -0.044838"/>
      <mass value="0.3"/>
      <inertia ixx="1.0e-2" ixy="0.0" ixz="0.0" iyy="1.0e-2" iyz="0.0" izz="1.0e-2"/>
    </inertial>
    <visual>
      <origin rpy="0 0 0" xyz="0 0 0"/>
      <geometry>
        <mesh filename="package://teo_description/meshes/arms/l_wrist_pitch.stl"/>
      </geometry>
      <!--<material name="teoGray"/>-->
    </visual>
    <collision>
      <origin rpy="0 0 0" xyz="0 0 0"/>
      <geometry>
        <mesh filename="package://teo_description/meshes/arms/l_wrist_pitch.stl"/>
      </geometry>
    </collision>
    <visual>
      <origin rpy="0 0 0" xyz="0 0 -0.056"/>
      <geometry>
        <mesh filename="package://teo_description/meshes/arms/l_wrist_sensorFT.stl"/>
      </geometry>
      <!--<material name="teoBlue"/>-->
    </visual>
    <collision>
      <origin rpy="0 0 0" xyz="0 0 -0.056"/>
      <geometry>
        <mesh filename="package://teo_description/meshes/arms/l_wrist_sensorFT.stl"/>
      </geometry>
    </collision>
    <!--<visual>
      <origin rpy="0 0 0" xyz="0 0 -0.056"/>
      <geometry>
        <mesh filename="package://teo_description/meshes/arms/l_hand.stl"/>
      </geometry>
      <material name="teoGray"/>
    </visual>
    <collision>
      <origin rpy="0 0 0" xyz="0 0 -0.056"/>
      <geometry>
        <mesh filename="package://teo_description/meshes/arms/l_hand.stl"/>
      </geometry>
    </collision>-->
  </link>
  <link name="FrontalRightShoulder">
    <inertial>
      <origin rpy="0 0 0" xyz="0.0 -0.0 0.0"/>
      <mass value="0.005"/>
      <inertia ixx="0.059121e-2" ixy="0.000603e-2" ixz="0.000103e-2" iyy="0.024956e-2" iyz="0.005131e-2" izz="0.050653e-2"/>
    </inertial>
    <visual>
      <origin rpy="0 0 0" xyz="0 0 0"/>
      <geometry>
        <mesh filename="package://teo_description/meshes/arms/r_shoulder_pitch.stl"/>
      </geometry>
      <material name="teoGray"/>
    </visual>
    <collision>
      <origin rpy="0 0 0" xyz="0 0 0"/>
      <geometry>
        <mesh filename="package://teo_description/meshes/arms/r_shoulder_pitch.stl"/>
      </geometry>
    </collision>
  </link>
  <link name="SagittalRightShoulder">
    <inertial>
      <origin rpy="0 0 0" xyz="0.0 -0.0 0.0"/>
      <mass value="0.005"/>
      <inertia ixx="0.018036e-2" ixy="-0.000773e-2" ixz="0.002406e-2" iyy="0.024499e-2" iyz="0.001826e-2" izz="0.013143e-2"/>
    </inertial>
    <visual>
      <origin rpy="0 0 0" xyz="0 0 0"/>
      <geometry>
        <mesh filename="package://teo_description/meshes/arms/r_shoulder_roll.stl"/>
      </geometry>
      <material name="teoGray"/>
    </visual>
    <collision>
      <origin rpy="0 0 0" xyz="0 0 0"/>
      <geometry>
        <mesh filename="package://teo_description/meshes/arms/r_shoulder_roll.stl"/>
      </geometry>
    </collision>
  </link>
  <link name="AxialRightShoulder">
    <inertial>
      <origin rpy="0 0 0" xyz="0.0 -0.0 0.0"/>
      <mass value="1.750625"/>
      <inertia ixx="0.227681e-2" ixy="0.0" ixz="0.0" iyy="0.224821e-2" iyz="-0.000684e-2" izz="0.032283e-2"/>
    </inertial>
    <visual>
      <origin rpy="0 0 0" xyz="0 0 -0.12126"/>
      <geometry>
        <mesh filename="package://teo_description/meshes/arms/r_shoulder_yaw.stl"/>
      </geometry>
      <material name="teoGray"/>
    </visual>
    <collision>
      <origin rpy="0 0 0" xyz="0 0 -0.12126"/>
      <geometry>
        <mesh filename="package://teo_description/meshes/arms/r_shoulder_yaw.stl"/>
      </geometry>
    </collision>
    <visual>
      <origin rpy="0 0 0" xyz="0 0 -0.27651"/>
      <geometry>
        <mesh filename="package://teo_description/meshes/arms/r_humerus.stl"/>
      </geometry>
      <material name="teoGray"/>
    </visual>
    <collision>
      <origin rpy="0 0 0" xyz="0 0 -0.27651"/>
      <geometry>
        <mesh filename="package://teo_description/meshes/arms/r_humerus.stl"/>
      </geometry>
    </collision>
    <visual>
      <origin rpy="0 0 0" xyz="0 0 -0.28351"/>
      <geometry>
        <mesh filename="package://teo_description/meshes/arms/r_union_humerus_elbow.stl"/>
      </geometry>
      <material name="teoGray"/>
    </visual>
    <collision>
      <origin rpy="0 0 0" xyz="0 0 -0.28351"/>
      <geometry>
        <mesh filename="package://teo_description/meshes/arms/r_union_humerus_elbow.stl"/>
      </geometry>
    </collision>
  </link>
  <link name="FrontalRightElbow">
    <inertial>
      <origin rpy="0 0 0" xyz="0.0 -0.001 -0.000588"/>
      <mass value="2.396"/>
      <inertia ixx="0.059390e-2" ixy="0.0" ixz="0.0" iyy="0.060871e-2" iyz="-0.0" izz="0.023257e-2"/>
    </inertial>
    <visual>
      <origin rpy="0 0 0" xyz="0 0 0"/>
      <geometry>
        <mesh filename="package://teo_description/meshes/arms/r_elbow_pitch.stl"/>
      </geometry>
      <material name="teoGray"/>
    </visual>
    <collision>
      <origin rpy="0 0 0" xyz="0 0 0"/>
      <geometry>
        <mesh filename="package://teo_description/meshes/arms/r_elbow_pitch.stl"/>
      </geometry>
    </collision>
    <visual>
      <origin rpy="0 0 0" xyz="0 0 -0.11324"/>
      <geometry>
        <mesh filename="package://teo_description/meshes/arms/r_elbow_link.stl"/>
      </geometry>
      <material name="teoGray"/>
    </visual>
    <collision>
      <origin rpy="0 0 0" xyz="0 0 -0.11324"/>
      <geometry>
        <mesh filename="package://teo_description/meshes/arms/r_elbow_link.stl"/>
      </geometry>
    </collision>
    <visual>
      <origin rpy="0 0 0" xyz="0 0 -0.11324"/>
      <geometry>
        <mesh filename="package://teo_description/meshes/arms/r_union_elbow_wrist.stl"/>
      </geometry>
      <material name="teoGray"/>
    </visual>
    <collision>
      <origin rpy="0 0 0" xyz="0 0 -0.11324"/>
      <geometry>
        <mesh filename="package://teo_description/meshes/arms/r_union_elbow_wrist.stl"/>
      </geometry>
    </collision>
  </link>
  <link name="AxialRightWrist">
    <inertial>
      <origin rpy="0 0 0" xyz="-0.004657 0.001356 0.035884"/>
      <mass value="0.005"/>
      <inertia ixx="0.004543e-2" ixy="0.000068e-2" ixz="0.000070e-2" iyy="0.003969e-2" iyz="-0.000074e-2" izz="0.002118e-2"/>
    </inertial>
    <visual>
      <origin rpy="0 0 0" xyz="0 0 0"/>
      <geometry>
        <mesh filename="package://teo_description/meshes/arms/r_wrist_yaw.stl"/>
      </geometry>
      <material name="teoGray"/>
    </visual>
    <collision>
      <origin rpy="0 0 0" xyz="0 0 0"/>
      <geometry>
        <mesh filename="package://teo_description/meshes/arms/r_wrist_yaw.stl"/>
      </geometry>
    </collision>
  </link>
  <link name="FrontalRightWrist">
    <inertial>
      <origin rpy="0 0 0" xyz="-0.002438 -0.004651 -0.044838"/>
      <mass value="0.3"/>
      <inertia ixx="1.0e-2" ixy="0.0" ixz="0.0" iyy="1.0e-2" iyz="0.0" izz="1.0e-2"/>
    </inertial>
    <visual>
      <origin rpy="0 0 0" xyz="0 0 0"/>
      <geometry>
        <mesh filename="package://teo_description/meshes/arms/r_wrist_pitch.stl"/>
      </geometry>
      <!--<material name="teoGray"/>-->
    </visual>
    <collision>
      <origin rpy="0 0 0" xyz="0 0 0"/>
      <geometry>
        <mesh filename="package://teo_description/meshes/arms/r_wrist_pitch.stl"/>
      </geometry>
    </collision>
    <visual>
      <origin rpy="0 0 0" xyz="0 0 -0.056"/>
      <geometry>
        <mesh filename="package://teo_description/meshes/arms/r_wrist_sensorFT.stl"/>
      </geometry>
      <!--<material name="teoBlue"/>-->
    </visual>
    <collision>
      <origin rpy="0 0 0" xyz="0 0 -0.056"/>
      <geometry>
        <mesh filename="package://teo_description/meshes/arms/r_wrist_sensorFT.stl"/>
      </geometry>
    </collision>
    <!--<visual>
      <origin rpy="0 0 0" xyz="0 0 -0.056"/>
      <geometry>
        <mesh filename="package://teo_description/meshes/arms/r_hand.stl"/>
      </geometry>
      <material name="teoGray"/>
    </visual>
    <collision>
      <origin rpy="0 0 0" xyz="0 0 -0.056"/>
      <geometry>
        <mesh filename="package://teo_description/meshes/arms/r_hand.stl"/>
      </geometry>
    </collision>-->
  </link>
  <joint name="FrontalLeftShoulder_joint" type="revolute">
    <parent link="FrontalTrunk"/>
    <child link="FrontalLeftShoulder"/>
    <origin rpy="0 0 0" xyz="-0.0 0.34692 0.305"/>
    <axis xyz="0 1.0 0"/>
    <limit effort="30.0" lower="-1.2217304764" upper="0.785398163397" velocity="3.0"/>
  </joint>
  <joint name="SagittalLeftShoulder_joint" type="revolute">
    <parent link="FrontalLeftShoulder"/>
    <child link="SagittalLeftShoulder"/>
    <origin rpy="0 0 0" xyz="0 0 0"/>
    <axis xyz="1 0 0"/>
    <limit effort="30.0" lower="-0.261799387799" upper="1.2217304764" velocity="3.0"/>
  </joint>
  <joint name="AxialLeftShoulder_joint" type="revolute">
    <parent link="SagittalLeftShoulder"/>
    <child link="AxialLeftShoulder"/>
    <origin rpy="0 0 0" xyz="0 0 0"/>
    <axis xyz="0 0 1"/>
    <limit effort="30.0" lower="-1.308996939" upper="0.174532925199" velocity="3.0"/>
  </joint>
  <joint name="FrontalLeftElbow_joint" type="revolute">
    <parent link="AxialLeftShoulder"/>
    <child link="FrontalLeftElbow"/>
    <origin rpy="0 0 0" xyz="0 0 -0.32901"/>
    <axis xyz="0 1.0 0"/>
    <limit effort="30.0" lower="-1.74532925199" upper="0.174532925199" velocity="3.0"/>
  </joint>
  <joint name="AxialLeftWrist_joint" type="revolute">
    <parent link="FrontalLeftElbow"/>
    <child link="AxialLeftWrist"/>
    <origin rpy="0 0 0" xyz="0 0 -0.202"/>
    <axis xyz="0 0 1"/>
    <limit effort="30.0" lower="-1.57079632679" upper="1.57079632679" velocity="3.0"/>
  </joint>
  <joint name="FrontalLeftWrist_joint" type="revolute">
    <parent link="AxialLeftWrist"/>
    <child link="FrontalLeftWrist"/>
    <origin rpy="0 0 0" xyz="0 0 0"/>
    <axis xyz="0 1.0 0"/>
    <limit effort="30.0" lower="-1.74532925199" upper="0.174532925199" velocity="3.0"/>
  </joint>
  <transmission name="l_shoulder_pitch_trans">
    <type>transmission_interface/SimpleTransmission</type>
    <joint name="FrontalLeftShoulder_joint">
      <hardwareInterface>PositionJointInterface</hardwareInterface>
    </joint>
    <actuator name="l_shoulder_pitch_motor">
      <hardwareInterface>PositionJointInterface</hardwareInterface>
      <mechanicalReduction>1.0</mechanicalReduction>
    </actuator>
  </transmission>
  <transmission name="l_shoulder_roll_trans">
    <type>transmission_interface/SimpleTransmission</type>
    <joint name="SagittalLeftShoulder_joint">
      <hardwareInterface>PositionJointInterface</hardwareInterface>
    </joint>
    <actuator name="l_shoulder_roll_motor">
      <hardwareInterface>PositionJointInterface</hardwareInterface>
      <mechanicalReduction>1.0</mechanicalReduction>
    </actuator>
  </transmission>
  <transmission name="l_shoulder_yaw_trans">
    <type>transmission_interface/SimpleTransmission</type>
    <joint name="AxialLeftShoulder_joint">
      <hardwareInterface>PositionJointInterface</hardwareInterface>
    </joint>
    <actuator name="l_shoulder_yaw_motor">
      <hardwareInterface>PositionJointInterface</hardwareInterface>
      <mechanicalReduction>1.0</mechanicalReduction>
    </actuator>
  </transmission>
  <transmission name="l_elbow_pitch_trans">
    <type>transmission_interface/SimpleTransmission</type>
    <joint name="FrontalLeftElbow_joint">
      <hardwareInterface>PositionJointInterface</hardwareInterface>
    </joint>
    <actuator name="l_elbow_pitch_motor">
      <hardwareInterface>PositionJointInterface</hardwareInterface>
      <mechanicalReduction>1.0</mechanicalReduction>
    </actuator>
  </transmission>
  <transmission name="l_wrist_yaw_trans">
    <type>transmission_interface/SimpleTransmission</type>
    <joint name="AxialLeftWrist_joint">
      <hardwareInterface>PositionJointInterface</hardwareInterface>
    </joint>
    <actuator name="l_wrist_yaw_motor">
      <hardwareInterface>PositionJointInterface</hardwareInterface>
      <mechanicalReduction>1.0</mechanicalReduction>
    </actuator>
  </transmission>
  <transmission name="l_wrist_pitch_trans">
    <type>transmission_interface/SimpleTransmission</type>
    <joint name="FrontalLeftWrist_joint">
      <hardwareInterface>PositionJointInterface</hardwareInterface>
    </joint>
    <actuator name="l_wrist_pitch_motor">
      <hardwareInterface>PositionJointInterface</hardwareInterface>
      <mechanicalReduction>1.0</mechanicalReduction>
    </actuator>
  </transmission>
  <joint name="FrontalRightShoulder_joint" type="revolute">
    <parent link="FrontalTrunk"/>
    <child link="FrontalRightShoulder"/>
    <origin rpy="0 0 0" xyz="-0.0 -0.34692 0.305"/>
    <axis xyz="0 1 0"/>
    <limit effort="30.0" lower="-0.785398163397" upper="1.2217304764" velocity="3.0"/>
  </joint>
  <joint name="SagittalRightShoulder_joint" type="revolute">
    <parent link="FrontalRightShoulder"/>
    <child link="SagittalRightShoulder"/>
    <origin rpy="0 0 0" xyz="0 0 0"/>
    <axis xyz="1 0 0"/>
    <limit effort="30.0" lower="-1.2217304764" upper="0.261799387799" velocity="3.0"/>
  </joint>
  <joint name="AxialRightShoulder_joint" type="revolute">
    <parent link="SagittalRightShoulder"/>
    <child link="AxialRightShoulder"/>
    <origin rpy="0 0 0" xyz="0 0 0"/>
    <axis xyz="0 0 1"/>
    <limit effort="30.0" lower="-0.174532925199" upper="1.308996939" velocity="3.0"/>
  </joint>
  <joint name="FrontalRightElbow_joint" type="revolute">
    <parent link="AxialRightShoulder"/>
    <child link="FrontalRightElbow"/>
    <origin rpy="0 0 0" xyz="0 0 -0.32901"/>
    <axis xyz="0 -1.0 0"/>
    <limit effort="30.0" lower="-0.174532925199" upper="1.74532925199" velocity="3.0"/>
  </joint>
  <joint name="AxialRightWrist_joint" type="revolute">
    <parent link="FrontalRightElbow"/>
    <child link="AxialRightWrist"/>
    <origin rpy="0 0 0" xyz="0 0 -0.202"/>
    <axis xyz="0 0 -1"/>
    <limit effort="30.0" lower="-1.57079632679" upper="1.57079632679" velocity="3.0"/>
  </joint>
  <joint name="FrontalRightWrist_joint" type="revolute">
    <parent link="AxialRightWrist"/>
    <child link="FrontalRightWrist"/>
    <origin rpy="0 0 0" xyz="0 0 0"/>
    <axis xyz="0 1 0"/>
    <limit effort="30.0" lower="-0.174532925199" upper="1.74532925199" velocity="3.0"/>
  </joint>
  <transmission name="r_shoulder_pitch_trans">
    <type>transmission_interface/SimpleTransmission</type>
    <joint name="FrontalRightShoulder_joint">
      <hardwareInterface>PositionJointInterface</hardwareInterface>
    </joint>
    <actuator name="r_shoulder_pitch_motor">
      <hardwareInterface>PositionJointInterface</hardwareInterface>
      <mechanicalReduction>1.0</mechanicalReduction>
    </actuator>
  </transmission>
  <transmission name="r_shoulder_roll_trans">
    <type>transmission_interface/SimpleTransmission</type>
    <joint name="SagittalRightShoulder_joint">
      <hardwareInterface>PositionJointInterface</hardwareInterface>
    </joint>
    <actuator name="r_shoulder_roll_motor">
      <hardwareInterface>PositionJointInterface</hardwareInterface>
      <mechanicalReduction>1.0</mechanicalReduction>
    </actuator>
  </transmission>
  <transmission name="r_shoulder_yaw_trans">
    <type>transmission_interface/SimpleTransmission</type>
    <joint name="AxialRightShoulder_joint">
      <hardwareInterface>PositionJointInterface</hardwareInterface>
    </joint>
    <actuator name="r_shoulder_yaw_motor">
      <hardwareInterface>PositionJointInterface</hardwareInterface>
      <mechanicalReduction>1.0</mechanicalReduction>
    </actuator>
  </transmission>
  <transmission name="r_elbow_pitch_trans">
    <type>transmission_interface/SimpleTransmission</type>
    <joint name="FrontalRightElbow_joint">
      <hardwareInterface>PositionJointInterface</hardwareInterface>
    </joint>
    <actuator name="r_elbow_pitch_motor">
      <hardwareInterface>PositionJointInterface</hardwareInterface>
      <mechanicalReduction>1.0</mechanicalReduction>
    </actuator>
  </transmission>
  <transmission name="r_wrist_yaw_trans">
    <type>transmission_interface/SimpleTransmission</type>
    <joint name="AxialRightWrist_joint">
      <hardwareInterface>PositionJointInterface</hardwareInterface>
    </joint>
    <actuator name="r_wrist_yaw_motor">
      <hardwareInterface>PositionJointInterface</hardwareInterface>
      <mechanicalReduction>1.0</mechanicalReduction>
    </actuator>
  </transmission>
  <transmission name="r_wrist_pitch_trans">
    <type>transmission_interface/SimpleTransmission</type>
    <joint name="FrontalRightWrist_joint">
      <hardwareInterface>PositionJointInterface</hardwareInterface>
    </joint>
    <actuator name="r_wrist_pitch_motor">
      <hardwareInterface>PositionJointInterface</hardwareInterface>
      <mechanicalReduction>1.0</mechanicalReduction>
    </actuator>
  </transmission>
 
  <!-- TEO visualization -->
  <!--xacro:unless complete_vis="$(arg complete_vis)">
    <xacro:include filename="$(find teo_description)/urdf/others/visualization.xacro" />
  </xacro:unless-->
  <!--xacro:include filename="$(find teo_description)/urdf/visual.xacro" /-->
  <material name="teoGray">
    <color rgba="0.6 0.6 0.55 1"/>
  </material>
  <material name="teoBlue">
    <color rgba="0.1 0.1 1.0 1"/>
  </material>
  <material name="teoBlack">
    <color rgba="0.0 0.0 0.0 1"/>
  </material>
</robot>
